[2025-10-30 13:33:35] [INFO    ] discord.client: logging in using static token
[2025-10-30 13:34:02] [INFO    ] discord.gateway: Shard ID None has connected to Gateway (Session ID: e651ab88912418dabc9af5580275f2b9).
[2025-10-30 13:36:10] [ERROR   ] discord.ext.commands.bot: Ignoring exception in command snipe
Traceback (most recent call last):
  File "/Users/aanayarahman/Library/Python/3.9/lib/python/site-packages/discord/ext/commands/core.py", line 266, in wrapped
    ret = await coro(*args, **kwargs)
  File "<string>", line 73, in snipe
  File "/Users/aanayarahman/Library/Python/3.9/lib/python/site-packages/discord/ext/commands/context.py", line 1102, in send
    return await super().send(
  File "/Users/aanayarahman/Library/Python/3.9/lib/python/site-packages/discord/abc.py", line 1703, in send
    data = await state.http.send_message(channel.id, params=params)
  File "/Users/aanayarahman/Library/Python/3.9/lib/python/site-packages/discord/http.py", line 654, in request
    async with self.__session.request(method, url, **kwargs) as response:
  File "/Users/aanayarahman/Library/Python/3.9/lib/python/site-packages/aiohttp/client.py", line 1510, in __aenter__
    self._resp: _RetType = await self._coro
  File "/Users/aanayarahman/Library/Python/3.9/lib/python/site-packages/aiohttp/client.py", line 779, in _request
    resp = await handler(req)
  File "/Users/aanayarahman/Library/Python/3.9/lib/python/site-packages/aiohttp/client.py", line 757, in _connect_and_send_request
    await resp.start(conn)
  File "/Users/aanayarahman/Library/Python/3.9/lib/python/site-packages/aiohttp/client_reqrep.py", line 539, in start
    message, payload = await protocol.read()  # type: ignore[union-attr]
  File "/Users/aanayarahman/Library/Python/3.9/lib/python/site-packages/aiohttp/streams.py", line 680, in read
    await self._waiter
aiohttp.client_exceptions.ServerDisconnectedError: Server disconnected

The above exception was the direct cause of the following exception:

Traceback (most recent call last):
  File "/Users/aanayarahman/Library/Python/3.9/lib/python/site-packages/discord/ext/commands/bot.py", line 1376, in invoke
    await ctx.command.invoke(ctx)
  File "/Users/aanayarahman/Library/Python/3.9/lib/python/site-packages/discord/ext/commands/core.py", line 1064, in invoke
    await injected(*ctx.args, **ctx.kwargs)  # type: ignore
  File "/Users/aanayarahman/Library/Python/3.9/lib/python/site-packages/discord/ext/commands/core.py", line 275, in wrapped
    raise CommandInvokeError(exc) from exc
discord.ext.commands.errors.CommandInvokeError: Command raised an exception: ServerDisconnectedError: Server disconnected
[2025-10-30 13:36:33] [ERROR   ] discord.client: Attempting a reconnect in 0.77s
Traceback (most recent call last):
  File "/Users/aanayarahman/Library/Python/3.9/lib/python/site-packages/aiohttp/connector.py", line 1283, in _wrap_create_connection
    return await self._loop.create_connection(*args, **kwargs, sock=sock)
  File "/Library/Developer/CommandLineTools/Library/Frameworks/Python3.framework/Versions/3.9/lib/python3.9/asyncio/base_events.py", line 1081, in create_connection
    transport, protocol = await self._create_connection_transport(
  File "/Library/Developer/CommandLineTools/Library/Frameworks/Python3.framework/Versions/3.9/lib/python3.9/asyncio/base_events.py", line 1111, in _create_connection_transport
    await waiter
ConnectionResetError

The above exception was the direct cause of the following exception:

Traceback (most recent call last):
  File "/Users/aanayarahman/Library/Python/3.9/lib/python/site-packages/discord/client.py", line 724, in connect
    self.ws = await asyncio.wait_for(coro, timeout=60.0)
  File "/Library/Developer/CommandLineTools/Library/Frameworks/Python3.framework/Versions/3.9/lib/python3.9/asyncio/tasks.py", line 481, in wait_for
    return fut.result()
  File "/Users/aanayarahman/Library/Python/3.9/lib/python/site-packages/discord/gateway.py", line 383, in from_client
    socket = await client.http.ws_connect(str(url))
  File "/Users/aanayarahman/Library/Python/3.9/lib/python/site-packages/discord/http.py", line 566, in ws_connect
    return await self.__session.ws_connect(url, **kwargs)
  File "/Users/aanayarahman/Library/Python/3.9/lib/python/site-packages/aiohttp/client.py", line 1076, in _ws_connect
    resp = await self.request(
  File "/Users/aanayarahman/Library/Python/3.9/lib/python/site-packages/aiohttp/client.py", line 779, in _request
    resp = await handler(req)
  File "/Users/aanayarahman/Library/Python/3.9/lib/python/site-packages/aiohttp/client.py", line 734, in _connect_and_send_request
    conn = await self._connector.connect(
  File "/Users/aanayarahman/Library/Python/3.9/lib/python/site-packages/aiohttp/connector.py", line 642, in connect
    proto = await self._create_connection(req, traces, timeout)
  File "/Users/aanayarahman/Library/Python/3.9/lib/python/site-packages/aiohttp/connector.py", line 1209, in _create_connection
    _, proto = await self._create_direct_connection(req, traces, timeout)
  File "/Users/aanayarahman/Library/Python/3.9/lib/python/site-packages/aiohttp/connector.py", line 1581, in _create_direct_connection
    raise last_exc
  File "/Users/aanayarahman/Library/Python/3.9/lib/python/site-packages/aiohttp/connector.py", line 1550, in _create_direct_connection
    transp, proto = await self._wrap_create_connection(
  File "/Users/aanayarahman/Library/Python/3.9/lib/python/site-packages/aiohttp/connector.py", line 1291, in _wrap_create_connection
    raise client_error(req.connection_key, exc) from exc
aiohttp.client_exceptions.ClientConnectorError: Cannot connect to host gateway-us-east1-c.discord.gg:443 ssl:default [None]
[2025-10-30 13:36:34] [ERROR   ] discord.client: Attempting a reconnect in 3.78s
Traceback (most recent call last):
  File "/Users/aanayarahman/Library/Python/3.9/lib/python/site-packages/aiohttp/connector.py", line 1283, in _wrap_create_connection
    return await self._loop.create_connection(*args, **kwargs, sock=sock)
  File "/Library/Developer/CommandLineTools/Library/Frameworks/Python3.framework/Versions/3.9/lib/python3.9/asyncio/base_events.py", line 1081, in create_connection
    transport, protocol = await self._create_connection_transport(
  File "/Library/Developer/CommandLineTools/Library/Frameworks/Python3.framework/Versions/3.9/lib/python3.9/asyncio/base_events.py", line 1111, in _create_connection_transport
    await waiter
ConnectionResetError

The above exception was the direct cause of the following exception:

Traceback (most recent call last):
  File "/Users/aanayarahman/Library/Python/3.9/lib/python/site-packages/discord/client.py", line 724, in connect
    self.ws = await asyncio.wait_for(coro, timeout=60.0)
  File "/Library/Developer/CommandLineTools/Library/Frameworks/Python3.framework/Versions/3.9/lib/python3.9/asyncio/tasks.py", line 481, in wait_for
    return fut.result()
  File "/Users/aanayarahman/Library/Python/3.9/lib/python/site-packages/discord/gateway.py", line 383, in from_client
    socket = await client.http.ws_connect(str(url))
  File "/Users/aanayarahman/Library/Python/3.9/lib/python/site-packages/discord/http.py", line 566, in ws_connect
    return await self.__session.ws_connect(url, **kwargs)
  File "/Users/aanayarahman/Library/Python/3.9/lib/python/site-packages/aiohttp/client.py", line 1076, in _ws_connect
    resp = await self.request(
  File "/Users/aanayarahman/Library/Python/3.9/lib/python/site-packages/aiohttp/client.py", line 779, in _request
    resp = await handler(req)
  File "/Users/aanayarahman/Library/Python/3.9/lib/python/site-packages/aiohttp/client.py", line 734, in _connect_and_send_request
    conn = await self._connector.connect(
  File "/Users/aanayarahman/Library/Python/3.9/lib/python/site-packages/aiohttp/connector.py", line 642, in connect
    proto = await self._create_connection(req, traces, timeout)
  File "/Users/aanayarahman/Library/Python/3.9/lib/python/site-packages/aiohttp/connector.py", line 1209, in _create_connection
    _, proto = await self._create_direct_connection(req, traces, timeout)
  File "/Users/aanayarahman/Library/Python/3.9/lib/python/site-packages/aiohttp/connector.py", line 1581, in _create_direct_connection
    raise last_exc
  File "/Users/aanayarahman/Library/Python/3.9/lib/python/site-packages/aiohttp/connector.py", line 1550, in _create_direct_connection
    transp, proto = await self._wrap_create_connection(
  File "/Users/aanayarahman/Library/Python/3.9/lib/python/site-packages/aiohttp/connector.py", line 1291, in _wrap_create_connection
    raise client_error(req.connection_key, exc) from exc
aiohttp.client_exceptions.ClientConnectorError: Cannot connect to host gateway-us-east1-c.discord.gg:443 ssl:default [None]
[2025-10-30 13:36:38] [ERROR   ] discord.client: Attempting a reconnect in 2.78s
Traceback (most recent call last):
  File "/Users/aanayarahman/Library/Python/3.9/lib/python/site-packages/aiohttp/connector.py", line 1283, in _wrap_create_connection
    return await self._loop.create_connection(*args, **kwargs, sock=sock)
  File "/Library/Developer/CommandLineTools/Library/Frameworks/Python3.framework/Versions/3.9/lib/python3.9/asyncio/base_events.py", line 1081, in create_connection
    transport, protocol = await self._create_connection_transport(
  File "/Library/Developer/CommandLineTools/Library/Frameworks/Python3.framework/Versions/3.9/lib/python3.9/asyncio/base_events.py", line 1111, in _create_connection_transport
    await waiter
ConnectionResetError

The above exception was the direct cause of the following exception:

Traceback (most recent call last):
  File "/Users/aanayarahman/Library/Python/3.9/lib/python/site-packages/discord/client.py", line 724, in connect
    self.ws = await asyncio.wait_for(coro, timeout=60.0)
  File "/Library/Developer/CommandLineTools/Library/Frameworks/Python3.framework/Versions/3.9/lib/python3.9/asyncio/tasks.py", line 481, in wait_for
    return fut.result()
  File "/Users/aanayarahman/Library/Python/3.9/lib/python/site-packages/discord/gateway.py", line 383, in from_client
    socket = await client.http.ws_connect(str(url))
  File "/Users/aanayarahman/Library/Python/3.9/lib/python/site-packages/discord/http.py", line 566, in ws_connect
    return await self.__session.ws_connect(url, **kwargs)
  File "/Users/aanayarahman/Library/Python/3.9/lib/python/site-packages/aiohttp/client.py", line 1076, in _ws_connect
    resp = await self.request(
  File "/Users/aanayarahman/Library/Python/3.9/lib/python/site-packages/aiohttp/client.py", line 779, in _request
    resp = await handler(req)
  File "/Users/aanayarahman/Library/Python/3.9/lib/python/site-packages/aiohttp/client.py", line 734, in _connect_and_send_request
    conn = await self._connector.connect(
  File "/Users/aanayarahman/Library/Python/3.9/lib/python/site-packages/aiohttp/connector.py", line 642, in connect
    proto = await self._create_connection(req, traces, timeout)
  File "/Users/aanayarahman/Library/Python/3.9/lib/python/site-packages/aiohttp/connector.py", line 1209, in _create_connection
    _, proto = await self._create_direct_connection(req, traces, timeout)
  File "/Users/aanayarahman/Library/Python/3.9/lib/python/site-packages/aiohttp/connector.py", line 1581, in _create_direct_connection
    raise last_exc
  File "/Users/aanayarahman/Library/Python/3.9/lib/python/site-packages/aiohttp/connector.py", line 1550, in _create_direct_connection
    transp, proto = await self._wrap_create_connection(
  File "/Users/aanayarahman/Library/Python/3.9/lib/python/site-packages/aiohttp/connector.py", line 1291, in _wrap_create_connection
    raise client_error(req.connection_key, exc) from exc
aiohttp.client_exceptions.ClientConnectorError: Cannot connect to host gateway-us-east1-c.discord.gg:443 ssl:default [None]
[2025-10-30 13:36:41] [ERROR   ] discord.client: Attempting a reconnect in 9.41s
Traceback (most recent call last):
  File "/Users/aanayarahman/Library/Python/3.9/lib/python/site-packages/aiohttp/connector.py", line 1283, in _wrap_create_connection
    return await self._loop.create_connection(*args, **kwargs, sock=sock)
  File "/Library/Developer/CommandLineTools/Library/Frameworks/Python3.framework/Versions/3.9/lib/python3.9/asyncio/base_events.py", line 1081, in create_connection
    transport, protocol = await self._create_connection_transport(
  File "/Library/Developer/CommandLineTools/Library/Frameworks/Python3.framework/Versions/3.9/lib/python3.9/asyncio/base_events.py", line 1111, in _create_connection_transport
    await waiter
ConnectionResetError

The above exception was the direct cause of the following exception:

Traceback (most recent call last):
  File "/Users/aanayarahman/Library/Python/3.9/lib/python/site-packages/discord/client.py", line 724, in connect
    self.ws = await asyncio.wait_for(coro, timeout=60.0)
  File "/Library/Developer/CommandLineTools/Library/Frameworks/Python3.framework/Versions/3.9/lib/python3.9/asyncio/tasks.py", line 481, in wait_for
    return fut.result()
  File "/Users/aanayarahman/Library/Python/3.9/lib/python/site-packages/discord/gateway.py", line 383, in from_client
    socket = await client.http.ws_connect(str(url))
  File "/Users/aanayarahman/Library/Python/3.9/lib/python/site-packages/discord/http.py", line 566, in ws_connect
    return await self.__session.ws_connect(url, **kwargs)
  File "/Users/aanayarahman/Library/Python/3.9/lib/python/site-packages/aiohttp/client.py", line 1076, in _ws_connect
    resp = await self.request(
  File "/Users/aanayarahman/Library/Python/3.9/lib/python/site-packages/aiohttp/client.py", line 779, in _request
    resp = await handler(req)
  File "/Users/aanayarahman/Library/Python/3.9/lib/python/site-packages/aiohttp/client.py", line 734, in _connect_and_send_request
    conn = await self._connector.connect(
  File "/Users/aanayarahman/Library/Python/3.9/lib/python/site-packages/aiohttp/connector.py", line 642, in connect
    proto = await self._create_connection(req, traces, timeout)
  File "/Users/aanayarahman/Library/Python/3.9/lib/python/site-packages/aiohttp/connector.py", line 1209, in _create_connection
    _, proto = await self._create_direct_connection(req, traces, timeout)
  File "/Users/aanayarahman/Library/Python/3.9/lib/python/site-packages/aiohttp/connector.py", line 1581, in _create_direct_connection
    raise last_exc
  File "/Users/aanayarahman/Library/Python/3.9/lib/python/site-packages/aiohttp/connector.py", line 1550, in _create_direct_connection
    transp, proto = await self._wrap_create_connection(
  File "/Users/aanayarahman/Library/Python/3.9/lib/python/site-packages/aiohttp/connector.py", line 1291, in _wrap_create_connection
    raise client_error(req.connection_key, exc) from exc
aiohttp.client_exceptions.ClientConnectorError: Cannot connect to host gateway-us-east1-c.discord.gg:443 ssl:default [None]
[2025-10-30 13:36:50] [ERROR   ] discord.client: Attempting a reconnect in 22.36s
Traceback (most recent call last):
  File "/Users/aanayarahman/Library/Python/3.9/lib/python/site-packages/aiohttp/connector.py", line 1283, in _wrap_create_connection
    return await self._loop.create_connection(*args, **kwargs, sock=sock)
  File "/Library/Developer/CommandLineTools/Library/Frameworks/Python3.framework/Versions/3.9/lib/python3.9/asyncio/base_events.py", line 1081, in create_connection
    transport, protocol = await self._create_connection_transport(
  File "/Library/Developer/CommandLineTools/Library/Frameworks/Python3.framework/Versions/3.9/lib/python3.9/asyncio/base_events.py", line 1111, in _create_connection_transport
    await waiter
ConnectionResetError

The above exception was the direct cause of the following exception:

Traceback (most recent call last):
  File "/Users/aanayarahman/Library/Python/3.9/lib/python/site-packages/discord/client.py", line 724, in connect
    self.ws = await asyncio.wait_for(coro, timeout=60.0)
  File "/Library/Developer/CommandLineTools/Library/Frameworks/Python3.framework/Versions/3.9/lib/python3.9/asyncio/tasks.py", line 481, in wait_for
    return fut.result()
  File "/Users/aanayarahman/Library/Python/3.9/lib/python/site-packages/discord/gateway.py", line 383, in from_client
    socket = await client.http.ws_connect(str(url))
  File "/Users/aanayarahman/Library/Python/3.9/lib/python/site-packages/discord/http.py", line 566, in ws_connect
    return await self.__session.ws_connect(url, **kwargs)
  File "/Users/aanayarahman/Library/Python/3.9/lib/python/site-packages/aiohttp/client.py", line 1076, in _ws_connect
    resp = await self.request(
  File "/Users/aanayarahman/Library/Python/3.9/lib/python/site-packages/aiohttp/client.py", line 779, in _request
    resp = await handler(req)
  File "/Users/aanayarahman/Library/Python/3.9/lib/python/site-packages/aiohttp/client.py", line 734, in _connect_and_send_request
    conn = await self._connector.connect(
  File "/Users/aanayarahman/Library/Python/3.9/lib/python/site-packages/aiohttp/connector.py", line 642, in connect
    proto = await self._create_connection(req, traces, timeout)
  File "/Users/aanayarahman/Library/Python/3.9/lib/python/site-packages/aiohttp/connector.py", line 1209, in _create_connection
    _, proto = await self._create_direct_connection(req, traces, timeout)
  File "/Users/aanayarahman/Library/Python/3.9/lib/python/site-packages/aiohttp/connector.py", line 1581, in _create_direct_connection
    raise last_exc
  File "/Users/aanayarahman/Library/Python/3.9/lib/python/site-packages/aiohttp/connector.py", line 1550, in _create_direct_connection
    transp, proto = await self._wrap_create_connection(
  File "/Users/aanayarahman/Library/Python/3.9/lib/python/site-packages/aiohttp/connector.py", line 1291, in _wrap_create_connection
    raise client_error(req.connection_key, exc) from exc
aiohttp.client_exceptions.ClientConnectorError: Cannot connect to host gateway-us-east1-c.discord.gg:443 ssl:default [None]
[2025-10-30 13:37:13] [ERROR   ] discord.client: Attempting a reconnect in 48.99s
Traceback (most recent call last):
  File "/Users/aanayarahman/Library/Python/3.9/lib/python/site-packages/aiohttp/connector.py", line 1283, in _wrap_create_connection
    return await self._loop.create_connection(*args, **kwargs, sock=sock)
  File "/Library/Developer/CommandLineTools/Library/Frameworks/Python3.framework/Versions/3.9/lib/python3.9/asyncio/base_events.py", line 1081, in create_connection
    transport, protocol = await self._create_connection_transport(
  File "/Library/Developer/CommandLineTools/Library/Frameworks/Python3.framework/Versions/3.9/lib/python3.9/asyncio/base_events.py", line 1111, in _create_connection_transport
    await waiter
ConnectionResetError

The above exception was the direct cause of the following exception:

Traceback (most recent call last):
  File "/Users/aanayarahman/Library/Python/3.9/lib/python/site-packages/discord/client.py", line 724, in connect
    self.ws = await asyncio.wait_for(coro, timeout=60.0)
  File "/Library/Developer/CommandLineTools/Library/Frameworks/Python3.framework/Versions/3.9/lib/python3.9/asyncio/tasks.py", line 481, in wait_for
    return fut.result()
  File "/Users/aanayarahman/Library/Python/3.9/lib/python/site-packages/discord/gateway.py", line 383, in from_client
    socket = await client.http.ws_connect(str(url))
  File "/Users/aanayarahman/Library/Python/3.9/lib/python/site-packages/discord/http.py", line 566, in ws_connect
    return await self.__session.ws_connect(url, **kwargs)
  File "/Users/aanayarahman/Library/Python/3.9/lib/python/site-packages/aiohttp/client.py", line 1076, in _ws_connect
    resp = await self.request(
  File "/Users/aanayarahman/Library/Python/3.9/lib/python/site-packages/aiohttp/client.py", line 779, in _request
    resp = await handler(req)
  File "/Users/aanayarahman/Library/Python/3.9/lib/python/site-packages/aiohttp/client.py", line 734, in _connect_and_send_request
    conn = await self._connector.connect(
  File "/Users/aanayarahman/Library/Python/3.9/lib/python/site-packages/aiohttp/connector.py", line 642, in connect
    proto = await self._create_connection(req, traces, timeout)
  File "/Users/aanayarahman/Library/Python/3.9/lib/python/site-packages/aiohttp/connector.py", line 1209, in _create_connection
    _, proto = await self._create_direct_connection(req, traces, timeout)
  File "/Users/aanayarahman/Library/Python/3.9/lib/python/site-packages/aiohttp/connector.py", line 1581, in _create_direct_connection
    raise last_exc
  File "/Users/aanayarahman/Library/Python/3.9/lib/python/site-packages/aiohttp/connector.py", line 1550, in _create_direct_connection
    transp, proto = await self._wrap_create_connection(
  File "/Users/aanayarahman/Library/Python/3.9/lib/python/site-packages/aiohttp/connector.py", line 1291, in _wrap_create_connection
    raise client_error(req.connection_key, exc) from exc
aiohttp.client_exceptions.ClientConnectorError: Cannot connect to host gateway-us-east1-c.discord.gg:443 ssl:default [None]
[2025-10-30 13:38:02] [ERROR   ] discord.client: Attempting a reconnect in 83.76s
Traceback (most recent call last):
  File "/Users/aanayarahman/Library/Python/3.9/lib/python/site-packages/aiohttp/connector.py", line 1283, in _wrap_create_connection
    return await self._loop.create_connection(*args, **kwargs, sock=sock)
  File "/Library/Developer/CommandLineTools/Library/Frameworks/Python3.framework/Versions/3.9/lib/python3.9/asyncio/base_events.py", line 1081, in create_connection
    transport, protocol = await self._create_connection_transport(
  File "/Library/Developer/CommandLineTools/Library/Frameworks/Python3.framework/Versions/3.9/lib/python3.9/asyncio/base_events.py", line 1111, in _create_connection_transport
    await waiter
ConnectionResetError

The above exception was the direct cause of the following exception:

Traceback (most recent call last):
  File "/Users/aanayarahman/Library/Python/3.9/lib/python/site-packages/discord/client.py", line 724, in connect
    self.ws = await asyncio.wait_for(coro, timeout=60.0)
  File "/Library/Developer/CommandLineTools/Library/Frameworks/Python3.framework/Versions/3.9/lib/python3.9/asyncio/tasks.py", line 481, in wait_for
    return fut.result()
  File "/Users/aanayarahman/Library/Python/3.9/lib/python/site-packages/discord/gateway.py", line 383, in from_client
    socket = await client.http.ws_connect(str(url))
  File "/Users/aanayarahman/Library/Python/3.9/lib/python/site-packages/discord/http.py", line 566, in ws_connect
    return await self.__session.ws_connect(url, **kwargs)
  File "/Users/aanayarahman/Library/Python/3.9/lib/python/site-packages/aiohttp/client.py", line 1076, in _ws_connect
    resp = await self.request(
  File "/Users/aanayarahman/Library/Python/3.9/lib/python/site-packages/aiohttp/client.py", line 779, in _request
    resp = await handler(req)
  File "/Users/aanayarahman/Library/Python/3.9/lib/python/site-packages/aiohttp/client.py", line 734, in _connect_and_send_request
    conn = await self._connector.connect(
  File "/Users/aanayarahman/Library/Python/3.9/lib/python/site-packages/aiohttp/connector.py", line 642, in connect
    proto = await self._create_connection(req, traces, timeout)
  File "/Users/aanayarahman/Library/Python/3.9/lib/python/site-packages/aiohttp/connector.py", line 1209, in _create_connection
    _, proto = await self._create_direct_connection(req, traces, timeout)
  File "/Users/aanayarahman/Library/Python/3.9/lib/python/site-packages/aiohttp/connector.py", line 1581, in _create_direct_connection
    raise last_exc
  File "/Users/aanayarahman/Library/Python/3.9/lib/python/site-packages/aiohttp/connector.py", line 1550, in _create_direct_connection
    transp, proto = await self._wrap_create_connection(
  File "/Users/aanayarahman/Library/Python/3.9/lib/python/site-packages/aiohttp/connector.py", line 1291, in _wrap_create_connection
    raise client_error(req.connection_key, exc) from exc
aiohttp.client_exceptions.ClientConnectorError: Cannot connect to host gateway-us-east1-c.discord.gg:443 ssl:default [None]
[2025-10-30 13:39:26] [ERROR   ] discord.client: Attempting a reconnect in 161.40s
Traceback (most recent call last):
  File "/Users/aanayarahman/Library/Python/3.9/lib/python/site-packages/aiohttp/connector.py", line 1283, in _wrap_create_connection
    return await self._loop.create_connection(*args, **kwargs, sock=sock)
  File "/Library/Developer/CommandLineTools/Library/Frameworks/Python3.framework/Versions/3.9/lib/python3.9/asyncio/base_events.py", line 1081, in create_connection
    transport, protocol = await self._create_connection_transport(
  File "/Library/Developer/CommandLineTools/Library/Frameworks/Python3.framework/Versions/3.9/lib/python3.9/asyncio/base_events.py", line 1111, in _create_connection_transport
    await waiter
ConnectionResetError

The above exception was the direct cause of the following exception:

Traceback (most recent call last):
  File "/Users/aanayarahman/Library/Python/3.9/lib/python/site-packages/discord/client.py", line 724, in connect
    self.ws = await asyncio.wait_for(coro, timeout=60.0)
  File "/Library/Developer/CommandLineTools/Library/Frameworks/Python3.framework/Versions/3.9/lib/python3.9/asyncio/tasks.py", line 481, in wait_for
    return fut.result()
  File "/Users/aanayarahman/Library/Python/3.9/lib/python/site-packages/discord/gateway.py", line 383, in from_client
    socket = await client.http.ws_connect(str(url))
  File "/Users/aanayarahman/Library/Python/3.9/lib/python/site-packages/discord/http.py", line 566, in ws_connect
    return await self.__session.ws_connect(url, **kwargs)
  File "/Users/aanayarahman/Library/Python/3.9/lib/python/site-packages/aiohttp/client.py", line 1076, in _ws_connect
    resp = await self.request(
  File "/Users/aanayarahman/Library/Python/3.9/lib/python/site-packages/aiohttp/client.py", line 779, in _request
    resp = await handler(req)
  File "/Users/aanayarahman/Library/Python/3.9/lib/python/site-packages/aiohttp/client.py", line 734, in _connect_and_send_request
    conn = await self._connector.connect(
  File "/Users/aanayarahman/Library/Python/3.9/lib/python/site-packages/aiohttp/connector.py", line 642, in connect
    proto = await self._create_connection(req, traces, timeout)
  File "/Users/aanayarahman/Library/Python/3.9/lib/python/site-packages/aiohttp/connector.py", line 1209, in _create_connection
    _, proto = await self._create_direct_connection(req, traces, timeout)
  File "/Users/aanayarahman/Library/Python/3.9/lib/python/site-packages/aiohttp/connector.py", line 1581, in _create_direct_connection
    raise last_exc
  File "/Users/aanayarahman/Library/Python/3.9/lib/python/site-packages/aiohttp/connector.py", line 1550, in _create_direct_connection
    transp, proto = await self._wrap_create_connection(
  File "/Users/aanayarahman/Library/Python/3.9/lib/python/site-packages/aiohttp/connector.py", line 1291, in _wrap_create_connection
    raise client_error(req.connection_key, exc) from exc
aiohttp.client_exceptions.ClientConnectorError: Cannot connect to host gateway-us-east1-c.discord.gg:443 ssl:default [None]
[2025-10-30 13:40:35] [ERROR   ] discord.ext.commands.bot: Ignoring exception in command snipe
Traceback (most recent call last):
  File "/Users/aanayarahman/Library/Python/3.9/lib/python/site-packages/aiohttp/connector.py", line 1283, in _wrap_create_connection
    return await self._loop.create_connection(*args, **kwargs, sock=sock)
  File "/Library/Developer/CommandLineTools/Library/Frameworks/Python3.framework/Versions/3.9/lib/python3.9/asyncio/base_events.py", line 1081, in create_connection
    transport, protocol = await self._create_connection_transport(
  File "/Library/Developer/CommandLineTools/Library/Frameworks/Python3.framework/Versions/3.9/lib/python3.9/asyncio/base_events.py", line 1111, in _create_connection_transport
    await waiter
ConnectionResetError

The above exception was the direct cause of the following exception:

Traceback (most recent call last):
  File "/Users/aanayarahman/Library/Python/3.9/lib/python/site-packages/discord/ext/commands/core.py", line 266, in wrapped
    ret = await coro(*args, **kwargs)
  File "<string>", line 77, in snipe
  File "/Users/aanayarahman/Library/Python/3.9/lib/python/site-packages/discord/abc.py", line 1703, in send
    data = await state.http.send_message(channel.id, params=params)
  File "/Users/aanayarahman/Library/Python/3.9/lib/python/site-packages/discord/http.py", line 654, in request
    async with self.__session.request(method, url, **kwargs) as response:
  File "/Users/aanayarahman/Library/Python/3.9/lib/python/site-packages/aiohttp/client.py", line 1510, in __aenter__
    self._resp: _RetType = await self._coro
  File "/Users/aanayarahman/Library/Python/3.9/lib/python/site-packages/aiohttp/client.py", line 779, in _request
    resp = await handler(req)
  File "/Users/aanayarahman/Library/Python/3.9/lib/python/site-packages/aiohttp/client.py", line 734, in _connect_and_send_request
    conn = await self._connector.connect(
  File "/Users/aanayarahman/Library/Python/3.9/lib/python/site-packages/aiohttp/connector.py", line 642, in connect
    proto = await self._create_connection(req, traces, timeout)
  File "/Users/aanayarahman/Library/Python/3.9/lib/python/site-packages/aiohttp/connector.py", line 1209, in _create_connection
    _, proto = await self._create_direct_connection(req, traces, timeout)
  File "/Users/aanayarahman/Library/Python/3.9/lib/python/site-packages/aiohttp/connector.py", line 1581, in _create_direct_connection
    raise last_exc
  File "/Users/aanayarahman/Library/Python/3.9/lib/python/site-packages/aiohttp/connector.py", line 1550, in _create_direct_connection
    transp, proto = await self._wrap_create_connection(
  File "/Users/aanayarahman/Library/Python/3.9/lib/python/site-packages/aiohttp/connector.py", line 1291, in _wrap_create_connection
    raise client_error(req.connection_key, exc) from exc
aiohttp.client_exceptions.ClientConnectorError: Cannot connect to host discord.com:443 ssl:default [None]

The above exception was the direct cause of the following exception:

Traceback (most recent call last):
  File "/Users/aanayarahman/Library/Python/3.9/lib/python/site-packages/discord/ext/commands/bot.py", line 1376, in invoke
    await ctx.command.invoke(ctx)
  File "/Users/aanayarahman/Library/Python/3.9/lib/python/site-packages/discord/ext/commands/core.py", line 1064, in invoke
    await injected(*ctx.args, **ctx.kwargs)  # type: ignore
  File "/Users/aanayarahman/Library/Python/3.9/lib/python/site-packages/discord/ext/commands/core.py", line 275, in wrapped
    raise CommandInvokeError(exc) from exc
discord.ext.commands.errors.CommandInvokeError: Command raised an exception: ClientConnectorError: Cannot connect to host discord.com:443 ssl:default [None]
[2025-10-30 13:42:07] [ERROR   ] discord.client: Attempting a reconnect in 357.67s
Traceback (most recent call last):
  File "/Users/aanayarahman/Library/Python/3.9/lib/python/site-packages/aiohttp/connector.py", line 1283, in _wrap_create_connection
    return await self._loop.create_connection(*args, **kwargs, sock=sock)
  File "/Library/Developer/CommandLineTools/Library/Frameworks/Python3.framework/Versions/3.9/lib/python3.9/asyncio/base_events.py", line 1081, in create_connection
    transport, protocol = await self._create_connection_transport(
  File "/Library/Developer/CommandLineTools/Library/Frameworks/Python3.framework/Versions/3.9/lib/python3.9/asyncio/base_events.py", line 1111, in _create_connection_transport
    await waiter
ConnectionResetError

The above exception was the direct cause of the following exception:

Traceback (most recent call last):
  File "/Users/aanayarahman/Library/Python/3.9/lib/python/site-packages/discord/client.py", line 724, in connect
    self.ws = await asyncio.wait_for(coro, timeout=60.0)
  File "/Library/Developer/CommandLineTools/Library/Frameworks/Python3.framework/Versions/3.9/lib/python3.9/asyncio/tasks.py", line 481, in wait_for
    return fut.result()
  File "/Users/aanayarahman/Library/Python/3.9/lib/python/site-packages/discord/gateway.py", line 383, in from_client
    socket = await client.http.ws_connect(str(url))
  File "/Users/aanayarahman/Library/Python/3.9/lib/python/site-packages/discord/http.py", line 566, in ws_connect
    return await self.__session.ws_connect(url, **kwargs)
  File "/Users/aanayarahman/Library/Python/3.9/lib/python/site-packages/aiohttp/client.py", line 1076, in _ws_connect
    resp = await self.request(
  File "/Users/aanayarahman/Library/Python/3.9/lib/python/site-packages/aiohttp/client.py", line 779, in _request
    resp = await handler(req)
  File "/Users/aanayarahman/Library/Python/3.9/lib/python/site-packages/aiohttp/client.py", line 734, in _connect_and_send_request
    conn = await self._connector.connect(
  File "/Users/aanayarahman/Library/Python/3.9/lib/python/site-packages/aiohttp/connector.py", line 642, in connect
    proto = await self._create_connection(req, traces, timeout)
  File "/Users/aanayarahman/Library/Python/3.9/lib/python/site-packages/aiohttp/connector.py", line 1209, in _create_connection
    _, proto = await self._create_direct_connection(req, traces, timeout)
  File "/Users/aanayarahman/Library/Python/3.9/lib/python/site-packages/aiohttp/connector.py", line 1581, in _create_direct_connection
    raise last_exc
  File "/Users/aanayarahman/Library/Python/3.9/lib/python/site-packages/aiohttp/connector.py", line 1550, in _create_direct_connection
    transp, proto = await self._wrap_create_connection(
  File "/Users/aanayarahman/Library/Python/3.9/lib/python/site-packages/aiohttp/connector.py", line 1291, in _wrap_create_connection
    raise client_error(req.connection_key, exc) from exc
aiohttp.client_exceptions.ClientConnectorError: Cannot connect to host gateway-us-east1-c.discord.gg:443 ssl:default [None]
